<?xml version="1.0"?>
<robot name="control_body" 

       xmlns:xi="http://www.w3.org/2001/XInclude"
       xmlns:gazebo="http://playerstage.sourceforge.net/gazebo/xmlschema/#gz"
       xmlns:model="http://playerstage.sourceforge.net/gazebo/xmlschema/#model"
       xmlns:sensor="http://playerstage.sourceforge.net/gazebo/xmlschema/#sensor"
       xmlns:body="http://playerstage.sourceforge.net/gazebo/xmlschema/#body"
       xmlns:geom="http://playerstage.sourceforge.net/gazebo/xmlschema/#geom"
       xmlns:joint="http://playerstage.sourceforge.net/gazebo/xmlschema/#joint"
       xmlns:interface="http://playerstage.sourceforge.net/gazebo/xmlschema/#interface"
       xmlns:rendering="http://playerstage.sourceforge.net/gazebo/xmlschema/#rendering"
       xmlns:renderable="http://playerstage.sourceforge.net/gazebo/xmlschema/#renderable"
       xmlns:controller="http://playerstage.sourceforge.net/gazebo/xmlschema/#controller"
       xmlns:physics="http://playerstage.sourceforge.net/gazebo/xmlschema/#physics">
  
    <link name="base_link"><inertial><mass value="0"/><inertia ixx="0" ixy="0" ixz="0" iyy="0" iyz="0" izz="0"/></inertial></link>


    <joint name="joint_x" type="prismatic"><parent link="base_link"/><child link="link_x"/><origin xyz= "0 0 0.0"/><axis xyz="1 0 0"/><limit effort="1000.0" lower="-1000" upper="1000" velocity="5"/></joint>
    <link name="link_x"><inertial><mass value="0"/><inertia ixx="0" ixy="0" ixz="0" iyy="0" iyz="0" izz="0"/></inertial></link>

    <joint name="joint_y" type="prismatic"><parent link="link_x"/><child link="link_y"/><origin xyz= "0 0 0.0"/><axis xyz="0 1 0"/><limit effort="1000.0" lower="-1000" upper="1000" velocity="5"/></joint>
    <link name="link_y"><inertial><mass value="0"/><inertia ixx="0" ixy="0" ixz="0" iyy="0" iyz="0" izz="0"/></inertial></link>

    <joint name="joint_z" type="prismatic"><parent link="link_y"/><child link="link_z"/><origin xyz= "0 0 0.0"/><axis xyz="0 0 1"/><limit effort="1000.0" lower="-1000" upper="1000" velocity="5"/></joint>
    <link name="link_z"><inertial><mass value="100"/><inertia ixx="0" ixy="0" ixz="0" iyy="0" iyz="0" izz="0"/></inertial></link>


    <joint name="joint_rz" type="revolute"><parent link="link_z"/><child link="link_rz"/><origin xyz= "0 0 0.0"/><axis xyz="0 0 1"/><limit effort="1000.0" lower="-1000" upper="1000" velocity="5"/></joint>
    <link name="link_rz"><inertial><mass value="0"/><inertia ixx="0" ixy="0" ixz="0" iyy="0" iyz="0" izz="0"/></inertial></link>

    <joint name="joint_rx" type="revolute"><parent link="link_rz"/><child link="link_rx"/><origin xyz= "0 0 0.0"/><axis xyz="1 0 0"/><limit effort="1000.0" lower="-1000" upper="1000" velocity="5"/></joint>
    <link name="link_rx"><inertial><mass value="0"/><inertia ixx="0" ixy="0" ixz="0" iyy="0" iyz="0" izz="0"/></inertial></link>
    
    <joint name="joint_tip" type="fixed">
        <parent link="link_rx"/>
        <child link="link_tip"/>
        <origin rpy="3.1415926535 0.0 0.0" xyz="0.0 0.0 0.014"/>
    </joint>

    <link name="link_tip">
        <inertial>
            <origin rpy="0 0 0" xyz="0 0 0"/>
            <mass value=".1"/>
            <inertia ixx="1" ixy="0" ixz="0" iyy="1" iyz="0" izz="1"/>
        </inertial>
        <visual>
            <origin rpy="0 0 0" xyz="0 0 0"/>
            <geometry>
                <mesh filename="tip.obj" scale="0.001 0.001 0.001"/>
            </geometry>
            <material name="blue">
                <color rgba="0.18039216, 0.50588235, 0.77254902 1"/>
            </material>
        </visual>
        <!-- <collision>
            <origin rpy="0 0 0" xyz="0 0 0"/>
            <geometry>
                <cylinder length="0.028" radius="0.001"/>
            </geometry>
        </collision> -->
        <!-- <collision>
            <origin rpy="0 0 0" xyz="0 0 0"/>
            <geometry>
                <mesh filename="tip.obj" scale="0.001 0.001 0.001"/>
            </geometry>
        </collision> -->
    </link>

    <joint name="joint_head" type="fixed">
        <parent link="link_tip"/>
        <child link="link_head"/>
        <origin rpy="3.1415926535 0.0 0.0" xyz="0.0 0.0 0.0"/>
    </joint>

    <link name="link_head">
        <contact>
            <lateral_friction value="1.0"/>
            <rolling_friction value="0.0001"/>
            <inertia_scaling value="3.0"/>
        </contact>
        <inertial>
            <origin rpy="0 0 0" xyz="0 0 0"/>
            <mass value=".1"/>
            <inertia ixx="1" ixy="0" ixz="0" iyy="1" iyz="0" izz="1"/>
        </inertial>
        <visual>
            <origin rpy="0 0 0" xyz="0 0 0"/>
            <geometry>
                <mesh filename="head.obj" scale="0.001 0.001 0.001"/>
            </geometry>
        </visual>
        <!-- <collision>
            <origin rpy="0 0 0" xyz="0 0 0"/>
            <geometry>
                <mesh filename="head.obj" scale="0.001 0.001 0.001"/>
            </geometry>
        </collision> -->
    </link>


    <joint name="joint_mid" type="fixed">
        <parent link="link_head"/>
        <child link="link_mid"/>
        <origin rpy="3.1415926535 0.0 0.0" xyz="0.0 0.0 0.108"/>
    </joint>

    <link name="link_mid">
        <contact>
            <lateral_friction value="1.0"/>
            <rolling_friction value="0.0001"/>
            <inertia_scaling value="3.0"/>
        </contact>
        <inertial>
            <origin rpy="0 0 0" xyz="0 0 0"/>
            <mass value=".1"/>
            <inertia ixx="1" ixy="0" ixz="0" iyy="1" iyz="0" izz="1"/>
        </inertial>
        <visual>
            <origin rpy="0 0 0" xyz="0 0 0"/>
            <geometry>
                <mesh filename="mid.obj" scale="0.001 0.001 0.001"/>
            </geometry>
            <material name="DarkGrey"/>
        </visual>
        <!-- <collision>
            <origin rpy="0 0 0" xyz="0 0 0"/>
            <geometry>
                <mesh filename="mid.obj" scale="0.001 0.001 0.001"/>
            </geometry>
        </collision> -->
    </link>

    <joint name="joint_suction_base" type="fixed">
        <parent link="link_mid"/>
        <child link="link_suction_base"/>
        <origin rpy="3.1415926535 0.0 0.0" xyz="0.0 0.0 0.0"/>
    </joint>

    <link name="link_suction_base">
        <contact>
            <lateral_friction value="1.0"/>
            <rolling_friction value="0.0001"/>
            <inertia_scaling value="3.0"/>
        </contact>
        <inertial>
            <origin rpy="0 0 0" xyz="0 0 0"/>
            <mass value=".1"/>
            <inertia ixx="1" ixy="0" ixz="0" iyy="1" iyz="0" izz="1"/>
        </inertial>
        <visual>
            <origin rpy="0 0 0" xyz="0 0 0"/>
            <geometry>
                <mesh filename="base.obj" scale="0.001 0.001 0.001"/>
            </geometry>
            <material name="DarkGrey"/>
        </visual>
        <!-- <collision>
            <origin rpy="0 0 0" xyz="0 0 0"/>
            <geometry>
                <mesh filename="base.obj" scale="0.001 0.001 0.001"/>
            </geometry>
        </collision> -->
    </link>

    <joint name="joint_arm" type="fixed">
        <parent link="link_suction_base"/>
        <child link="link_arm"/>
        <origin rpy="3.1415926535 0.0 0.0" xyz="0.0 0.0 0.075"/>
    </joint>

    <link name="link_arm">
        <inertial>
            <origin rpy="0 0 0" xyz="0 0 0"/>
            <mass value=".1"/>
            <inertia ixx="1" ixy="0" ixz="0" iyy="1" iyz="0" izz="1"/>
        </inertial>
        <visual>
            <origin rpy="0 0 0" xyz="0 0 0"/>
            <geometry>
                <cylinder length="0.1" radius="0.038"/>
            </geometry>
            <material name="DarkGrey"/>
        </visual>
        <!-- <collision>
            <origin rpy="0 0 0" xyz="0 0 0"/>
            <geometry>
                <cylinder length="0.1" radius="0.038"/>
            </geometry>
        </collision> -->
    </link>

</robot>